Workbook

Sheet Instructions
A1: MS Excel Practical Exam
A2: Total Questions: 30
A3: Difficulty Level: Medium
A4: Syllabus: Formulas, Logical Functions, Lookups, INDEX-MATCH, Pivot Tables & Charts, Data Analysis
A5: Attempt all questions using appropriate Excel tools/functions.

Sheet Sales_Data
A1: Order_ID | B1: Region | C1: Salesperson | D1: Product | E1: Quantity | F1: Unit_Price | G1: Sales_Date
A2: 301 | B2: North | C2: Amit | D2: Laptop | E2: 2 | F2: 45000 | G2: 05-01-2025
A3: 302 | B3: South | C3: Riya | D3: Mobile | E3: 5 | F3: 15000 | G3: 07-01-2025
A4: 303 | B4: East | C4: Kunal | D4: Tablet | E4: 3 | F4: 18000 | G4: 10-01-2025
A5: 304 | B5: West | C5: Neha | D5: Laptop | E5: 1 | F5: 45000 | G5: 12-01-2025
A6: 305 | B6: North | C6: Amit | D6: Mobile | E6: 4 | F6: 15000 | G6: 15-01-2025
A7: 306 | B7: South | C7: Riya | D7: Laptop | E7: 2 | F7: 45000 | G7: 18-01-2025

Sheet Student_Marks
A1: Student_ID | B1: Name | C1: Maths | D1: Statistics | E1: Excel | F1: Attendance_%
A2: 1 | B2: Rahul | C2: 78 | D2: 82 | E2: 85 | F2: 92
A3: 2 | B3: Sneha | C3: 88 | D3: 91 | E3: 90 | F3: 96
A4: 3 | B4: Arjun | C4: 65 | D4: 70 | E4: 72 | F4: 85
A5: 4 | B5: Pooja | C5: 92 | D5: 89 | E5: 94 | F5: 98
A6: 5 | B6: Vikas | C6: 55 | D6: 60 | E6: 58 | F6: 80

Sheet Product_Master
A1: Product | B1: Category | C1: GST_%
A2: Laptop | B2: Electronics | C2: 18
A3: Mobile | B3: Electronics | C3: 12
A4: Tablet | B4: Electronics | C4: 12

Sheet Questions
A1: 1. Calculate Total Sales for each order (Quantity × Unit_Price). | J1: 2
A2: 2. Calculate GST Amount using VLOOKUP from Product_Master. | J2: 2
A3: 3. Find Final Amount payable (Total Sales + GST). | J3: 2
A4: 4. Find Grand Total of Final Amount. | J4: 2
A5: 5. Count total number of orders using COUNTA. | J5: 2
A6: 6. Find Region-wise total sales using SUMIF. | J6: 2
A7: 7. Use IF to classify Quantity as High (>3) or Low (<=3). | J7: 2
A8: 8. Find the maximum and minimum Final Amount. | J8: 2
A9: 9. Extract month name from Sales_Date. | J9: 2
A10: 10. Sort Sales_Data by Final Amount (Descending). | J10: 2
A11: 11. Use INDEX-MATCH to fetch Product Category. | J11: 2
A12: 12. Calculate average marks of each student. | J12: 2
... A30: 30. Protect the Student_Marks sheet. | J30: 2
J32: =SUM(J1:J30) -> 60

Sheet Pivot Table 16
A3: Row Labels | B3: Sum of Total Sales
A4: Laptop | B4: 225000
A5: Mobile | B5: 135000
A6: Tablet | B6: 54000
A7: Grand Total | B7: 414000

Sheet Pivot table 18
A3: Row Labels | B3: Sum of Total Sales
A4: Laptop | B4: 225000
A5: Mobile | B5: 135000
A6: Tablet | B6: 54000
A7: Grand Total | B7: 414000

Sheet Pivot table 17
A3: Row Labels | B3: Sum of Total Sales
A4: East | B4: 54000
A5: North | B5: 150000
A6: South | B6: 165000
A7: West | B7: 45000
A8: Grand Total | B8: 414000

Sheet Pivot table 19 
A1: Row Labels | B1: Sum of Excel
A2: Arjun | B2: 72
A3: Pooja | B3: 94
A4: Rahul | B4: 85
A5: Sneha | B5: 90
A6: Vikas | B6: 58
A7: Grand Total | B7: 399

Sheet Ans 
A1: Q-1
A2: 1. Calculate Total Sales for each order (Quantity × Unit_Price).
A3: Order_ID | B3: Region | C3: Salesperson | D3: Product | E3: Quantity | F3: Unit_Price | G3: Sales_Date | H3: Total Sales
A4: 301 | B4: North | C4: Amit | D4: Laptop | E4: 2 | F4: 45000 | G4: 05-01-2025 | H4: =E4*F4 -> 90000
A5: 302 | B5: South | C5: Riya | D5: Mobile | E5: 5 | F5: 15000 | G5: 07-01-2025 | H5: =E5*F5 -> 75000
A6: 303 | B6: East | C6: Kunal | D6: Tablet | E6: 3 | F6: 18000 | G6: 10-01-2025 | H6: =E6*F6 -> 54000
A7: 304 | B7: West | C7: Neha | D7: Laptop | E7: 1 | F7: 45000 | G7: 12-01-2025 | H7: =E7*F7 -> 45000
A8: 305 | B8: North | C8: Amit | D8: Mobile | E8: 4 | F8: 15000 | G8: 15-01-2025 | H8: =E8*F8 -> 60000
A9: 306 | B9: South | C9: Riya | D9: Laptop | E9: 2 | F9: 45000 | G9: 18-01-2025 | H9: =E9*F9 -> 90000
A12: Q-2
A13: 2. Calculate GST Amount using VLOOKUP from Product_Master.
A14: Order_ID | B14: Region | C14: Salesperson | D14: Product | E14: Quantity | F14: Unit_Price | G14: Sales_Date | H14: Total Sales | I14: GST | J14: GST_amount
A15: 301 | B15: North | C15: Amit | D15: Laptop | E15: 2 | F15: 45000 | G15: 05-01-2025 | H15: =E15*F15 -> 90000 | I15: 18 | J15: =I15*H4/100 -> 16200
A16: 302 | B16: South | C16: Riya | D16: Mobile | E16: 5 | F16: 15000 | G16: 07-01-2025 | H16: =E16*F16 -> 75000 | I16: 12 | J16: =I16*H5/100 -> 9000
A17: 303 | B17: East | C17: Kunal | D17: Tablet | E17: 3 | F17: 18000 | G17: 10-01-2025 | H17: =E17*F17 -> 54000 | I17: 12 | J17: =I17*H6/100 -> 6480
A18: 304 | B18: West | C18: Neha | D18: Laptop | E18: 1 | F18: 45000 | G18: 12-01-2025 | H18: =E18*F18 -> 45000 | I18: 18 | J18: =I18*H7/100 -> 8100
A19: 305 | B19: North | C19: Amit | D19: Mobile | E19: 4 | F19: 15000 | G19: 15-01-2025 | H19: =E19*F19 -> 60000 | I19: 12 | J19: =I19*H8/100 -> 7200
A20: 306 | B20: South | C20: Riya | D20: Laptop | E20: 2 | F20: 45000 | G20: 18-01-2025 | H20: =E20*F20 -> 90000 | I20: 18 | J20: =I20*H9/100 -> 16200
A23: Q-3
A24: 3. Find Final Amount payable (Total Sales + GST).
A25: Order_ID | B25: Region | C25: Salesperson | D25: Product | E25: Quantity | F25: Unit_Price | G25: Sales_Date | H25: Total Sales | I25: GST | J25: GST_amount | K25: Total Amount payable
A26: 301 | B26: North | C26: Amit | D26: Laptop | E26: 2 | F26: 45000 | G26: 05-01-2025 | H26: =E26*F26 -> 90000 | I26: 18 | J26: =I26*H26/100 -> 16200 | K26: =H26+J26 -> 106200
A27: 302 | B27: South | C27: Riya | D27: Mobile | E27: 5 | F27: 15000 | G27: 07-01-2025 | H27: =E27*F27 -> 75000 | I27: 12 | J27: =I27*H27/100 -> 9000 | K27: =H27+J27 -> 84000
A28: 303 | B28: East | C28: Kunal | D28: Tablet | E28: 3 | F28: 18000 | G28: 10-01-2025 | H28: =E28*F28 -> 54000 | I28: 12 | J28: =I28*H28/100 -> 6480 | K28: =H28+J28 -> 60480
A29: 304 | B29: West | C29: Neha | D29: Laptop | E29: 1 | F29: 45000 | G29: 12-01-2025 | H29: =E29*F29 -> 45000 | I29: 18 | J29: =I29*H29/100 -> 8100 | K29: =H29+J29 -> 53100
A30: 305 | B30: North | C30: Amit | D30: Mobile | E30: 4 | F30: 15000 | G30: 15-01-2025 | H30: =E30*F30 -> 60000 | I30: 12 | J30: =I30*H30/100 -> 7200 | K30: =H30+J30 -> 67200
A31: 306 | B31: South | C31: Riya | D31: Laptop | E31: 2 | F31: 45000 | G31: 18-01-2025 | H31: =E31*F31 -> 90000 | I31: 18 | J31: =I31*H31/100 -> 16200 | K31: =H31+J31 -> 106200
A34: Q-4
A35: 4. Find Grand Total of Final Amount.
A36: Total Final Amount | B36: =SUM(K26:K31) -> 477180
A41: Q-5
A42: 5. Count total number of orders using COUNTA.
A43: Total Number orders | B43: =COUNTA(A4:A9) -> 6
A46: Q-6
A47: 6. Find Region-wise total sales using SUMIF.
A48: Region -Wise Total Sales | B48: North | C48: =SUMIF($B$4:$B$9,B4,$H$4:$H$9) -> 150000
B49: Sounth | C49: =SUMIF($B$4:$B$9,B5,$H$4:$H$9) -> 165000
B50: East | C50: =SUMIF(B4:$B$9,B6,$H$4:$H$9) -> 54000
B51: West | C51: =SUMIF($B$4:$B$9,B7,$H$4:$H$9) -> 45000
A54: Q-7
...
